Workbook

Sheet Aileron
A5: MTOW | B5: =[1]!Table9[[#Headers],[5850]]/2.204623 -> 2653.5149 | C5: kg | D5: INPUT VALUES IN ORANGE!!! | G5: bai/b | H5: 60 | I5: % | K5: CHT | L5: =B8/Aileron!L6 -> 1.2919793 | M5: m
A6: AR | B6: ='[1]Sref and POWER SIZING'!$B$17 -> 7.8 | G6: ba0/b | H6: 90 | I6: % | K6: bHT | L6: =SQRT(Aileron!B17*Aileron!B8) -> 4.9095214 | M6: m
A7: S | B7: ='[1]Sref and POWER SIZING'!$H$80 -> 23.951179 | C7: sq m | K7: CrootHT | L7: =((3/2)*L5)/( (1+B20+B20^2)/(1+B20)) -> 1.4296492 | M7: m
A8: Sh | B8: 6.343 | C8: sq m | G8: Ca/C | H8: 20 | I8: % | K8: t/c HT | L8: 0.09
A9: Sv | B9: 4.9876 | C9: sq m
A10: Vs | B10: ='[1]Sref and POWER SIZING'!$B$11 -> 61 | C10: knots = | D10: =B10*0.514 -> 31.354 | E10: m/s | G10: τ | H10: 0.41 | I10: obtain value from figure 12.12 Sadraey
A11: CLαw | B11: =[1]!Table21[[#This Row],[Column4]] -> 4.732115
A12: λWING | B12: ='[1]Wing & Airfoil'!$B$5 -> 0.45
A13: bWING | B13: =SQRT(B7*B6) -> 13.668182 | C13: m | G13: yo | H13: =H6*B13/200 -> 6.1506818
A14: Croot_WING | B14: =(3/2)*B15*((1+B12)/(1+B12+B12^2)) -> 2.3063963 | G14: yi | H14: =H5*B13/200 -> 4.1004546
A15: Cw | B15: =B13/B6 -> 1.752331 | C15: m | G15: ClδA | H15: =(2*B11*H10*B14/(B7*B13))*((0.5*H13^2+(2/3*(B12-1)/B13*H13^3))-(0.5*H14^2+(2/3*(B12-1)/B13*H14^3))) -> 0.16719853
A16: Ixx | B16: =B13^2*B5*0.34^2/(4*9.81) -> 1460.4001 | C16: consult Raymer table 16.1 | G16: δAmax | H16: 17 | I16: deg
A17: ARh | B17: 3.8
A18: Vapp/Vs | B18: 1.3 | C18: Vapp = | D18: =B18*D10 -> 40.7602 | E18: m/s | G18: Cl | H18: =H15*H16/57.2958 -> 0.049608784
A19: ɅHT | B19: 5 | C19: deg
A20: λHT | B20: 0.8 | D20: CDR | E20: 0.7 | F20: (0.7-1.2) | G20: φ1 | H20: =B16*LN(E23^2)/(1.225*E22^3*(B7+B8+B9)*E20) -> 9.403169 | I20: rad | J20: =H20*57.2958 -> 538.76209 | K20: deg
A21: LA | B21: =0.5*1.225*D18^2*B7*H18*B13 -> 16526.273 | E21: 40 | G21: P | H21: =E23^2/(2*H20) -> 2.843766 | I21: rad/s2
A22: Drag moment arm(%wing span) | D22: yD | E22: =E21*B13/200 -> 2.7336364
D23: Pss | E23: =SQRT((2*B21)/(1.225*(B7+B8+B9)*E20*E22^3) ) -> 7.3130585 | G23: t2 | H23: =SQRT(2*30/(H21*57.3)) -> 0.60680812 | I23: s | J23: t2<treq
G24: treq | H24: 1.8 | I24: s | J24: always ensure this is the case
A25: aileron geometry
A26: bA | B26: =H13-H14 -> 2.0502273 | C26: m
A27: CA | B27: =H8*B15/100 -> 0.3504662 | C27: m
A28: AA(both) | B28: =2*B27*B26 -> 1.4370707 | C28: m2
A29: SA/S | B29: =B28/B7 -> 0.06
A32: φdes | B32: t2
A33: 0 | B33: =SQRT((2*A33)/(H$21*57.2958)) -> 0
A34: 5 | B34: =SQRT((2*A34)/(H$21*57.2958)) -> 0.24773746
A35: 10 | B35: =SQRT((2*A35)/(H$21*57.2958)) -> 0.35035367
A36: 15 | B36: =SQRT((2*A36)/(H$21*57.2958)) -> 0.42909386
A37: 20 | B37: =SQRT((2*A37)/(H$21*57.2958)) -> 0.49547492
A38: 25 | B38: =SQRT((2*A38)/(H$21*57.2958)) -> 0.5539578
A39: 30 | B39: =SQRT((2*A39)/(H$21*57.2958)) -> 0.60683036
A40: 40 | B40: =SQRT((2*A40)/(H$21*57.2958)) -> 0.70070735
A41: 60 | B41: =SQRT((2*A41)/(H$21*57.2958)) -> 0.85818773
A43: t2 | D43: φreq
A44: =H$23 -> 0.60680812 | B44: 0 | C44: 0.001 | D44: 30
A45: =H$23 -> 0.60680812 | B45: 0.1 | C45: 0.005 | D45: 30
A46: =H$23 -> 0.60680812 | B46: 60 | C46: 0.85 | D46: 30

Sheet Elevator
A1: δEmax | B1: -21 | C1: deg | D1: Wing | G1: Tail
A2: Iyy | B2: =Aileron!B13^2*Aileron!B5*0.29^2/(4*9.81) -> 1062.4537 | C2: kgm2 | D2: clflapto | E2: 0.8 | G2: Clαh | H2: 0.101 | I2: 1/deg
A3: Df | B3: 1.3462 | C3: m | D3: cmawf | E3: ='[1]Wing & Airfoil'!$L$15 -> -0.071677464 | G3: CLαh | H3: =(H2/(1+(H2/(3.142*Aileron!B17))))*57.3 -> 5.7387545 | I3: 1/rad
A4: Lf | B4: 9.1 | C4: m | D4: iw | E4: ='[1]Wing & Airfoil'!$B$15 -> 1.8 | F4: deg | G4: ih | H4: -0.35661 | I4: deg
A5: cdoto | B5: ='[1]Sref and POWER SIZING'!$B$25 -> 0.030219944 | D5: ho | E5: ='[1]Wing & Airfoil'!$B$29 -> 0.247 | G5: λh | H5: =Aileron!B20 -> 0.8
A6: Vc | B6: ='[2]take-off'!$B$16 -> 140 | C6: KTAS | D6: αsto | E6: ='[1]Wing & Airfoil'!$B$25 -> 14 | G6: ηh | H6: 0.98
A7: CLO | B7: ='[1]Wing & Airfoil'!$L$14 -> 0.33033962 | D7: clto | E7: ='[2]take-off'!$M$17 -> 1.4869053 | G7: αhs | H7: 14 | I7: deg
A8: CDOC | B8: 0.0258 | D8: cmo | E8: =E3 -> -0.071677464 | G8: αtwist | H8: 0 | I8: deg
A9: e | B9: ='[1]Sref and POWER SIZING'!$B$18 -> 0.75552605 | G9: lh | H9: 5.1 | I9: m
A10: VR | B10: =Aileron!D10 -> 31.354 | C10: clc | D10: ='[1]Sref and POWER SIZING'!$G$5 -> 0.40822441 | E10: cdto | F10: =B5+(B12*E7^2) -> 0.14962326
A11: µ | B11: ='[1]Sref and POWER SIZING'!$B$29 -> 0.090147052 | G11: DTO | H11: =0.5*1.225*B10^2*Aileron!B7*Elevator!F10 -> 2157.8339 | I11: N
A12: k | B12: =1/(3.142*(B9*Aileron!B6)) -> 0.054006965 | D12: Öinitial | E12: 9 | F12: deg/s2 | G12: LTO =Lwf | H12: =0.5*1.225*B10^2*Aileron!B7*Elevator!E7 -> 21443.823 | I12: N
A13: Thrust | B13: 3800 | C13: N
A14: Ff | B14: =B11*(9.81*Aileron!B5-Elevator!H12) -> 413.51881 | C14: N
A15: a | B15: =(B13-H11-B14)/Aileron!B5 -> 0.46302632 | C15: m/sq s | D15: Macwf | E15: =0.5*1.225*B10^2*E3*Aileron!B7*Aileron!B15 -> -1811.4138 | F15: Nm
D16: MW | E16: =-Aileron!B5*9.81*(B17-B18) -> -16111.616 | F16: Nm | G16: h | H16: 0.477468
A17: xmg | B17: 0 | D17: MD | E17: =H11*(B19-B20) -> 3452.5343 | F17: Nm | G17: ho | H17: 0.17684
A18: xcg | B18: -0.61894 | C18: m | D18: MT | E18: =-B13*(B23-B20) -> -4940 | F18: Nm
A19: zD | B19: 1.6 | D19: MLwf | E19: =H12*(B17-B21) -> 10238.739 | F19: Nm
A20: zmg | B20: 0 | D20: Ma | E20: =Aileron!B5*B15*(B22-B20) -> 1842.9709 | F20: Nm
A21: xacwf | B21: -0.477468
A22: zcg | B22: 1.5 | D22: Lh | E22: =(E19+E15+E20+E16+E17+E18-(B2*E12/57.3))/(B24-B17) -> -1621.5491 | F22: N | G22: ϵo | H22: =2*E7/(3.142*Aileron!B6) -> 0.12134239 | I22: rad
A23: zT | B23: 1.3 | D23: CLh | E23: =2*E22/(1.225*B10^2*Aileron!B8) -> -0.42456422 | G23: = | H23: =H22*57.3 -> 6.9529187 | I23: deg
A24: xach | B24: 4.622532 | G24: δϵ/δα | H24: =2*Aileron!B11/(3.142*Aileron!B6) -> 0.38617531 | I24: deg/deg
G25: ϵ | H25: =H22+(H24*E4/57.3) -> 0.13347355 | I25: rad
A26: ah | B26: =E4+H4-H26 -> -6.2046442 | G26: = | H26: =H25*57.3 -> 7.6480342 | I26: deg
A27: τe | B27: =((B26/57.3)+(E23/H3))/(B1/57.3) -> 0.49732427 | C27: use figure 12.12 Sadraey to determine
A29: CE/Ch | B29: 0.35 | F29: Cmα | G29: =Aileron!B11*((H16-H17)/Aileron!B15)-(H3*H6*(Aileron!B8/Aileron!B7)*(B24/Aileron!B15)*(1-Elevator!H24)) -> -1.5998434 | H29: 1/rad | I29: αTO | J29: =E6-2 -> 12 | K29: deg
A30: ∆αOE | B30: =-1.15*B29*B1 -> 8.4525 | F30: q | G30: =0.5*1.225*(B6*0.514)^2 -> 3171.673 | H30: Pa | I30: αhTO | J30: =(J29*(1-H24))+H4-H23 -> 0.056367578 | K30: deg | L30: αhTO must always be less than αhs
A31: VH | B31: =B24*Aileron!B8/(Aileron!B7*Aileron!B15) -> 0.69860485 | F31: CL1 | G31: =2*Aileron!B5*9.81/(1.225*(B6*0.514)^2*Aileron!B7) -> 0.34266934 | I31: αhs | J31: =(H7-5.3) -> 8.7 | K31: deg
A32: CmδE | B32: =-H3*H6*B31*B40*B27 -> -1.9539569 | C32: 1/rad | F32: δE | G32: =-(( ( B13*(B22-B23)/(G30*Aileron!B7*Aileron!B15)+Elevator!E8))*Aileron!B11 +(Elevator!G31-Elevator!B7)*Elevator!G29)/ ((Aileron!B11*Elevator!B32)-(Elevator!G29*Elevator!B33)) -> -0.041171245 | H32: rad
A33: CLδE | B33: =H3*H6*(Aileron!B8/Aileron!B7)*B40*B27 -> 0.74071509 | C33: 1/rad | G33: =G32*57.3 -> -2.3591124 | H33: deg
A34: CLhδE | B34: =H3*B27 -> 2.8540219 | C34: 1/rad
N36: SEA LEVEL | X36: CRUISE
B37: DIMENSIONS | H37: KTAS | I37: VHaft | J37: qSL | K37: CL1(S-L) | L37: δE AFT | M37: δE AFT(deg) | N37: δE forward | O37: δE forward deg | P37: lhforward | Q37: vhforward | R37: Cmαforward | S37: CmδEforward | T37: h-ho(forward) | U37: CL1(CRUISE) | V37: qcruise | W37: δE AFT | X37: δE AFT deg | Y37: δE forward | Z37: δE forward deg
H38: 61 | I38: =B$34 -> 2.8540219 | J38: =0.5*1.225*(H38*0.514)^2 -> 602.13241 | K38: =(2*Aileron!B$5*9.81)/(1.225*Aileron!B$7*(Elevator!H38*0.514)^2) -> 1.8049769 | L38: =-(( (B$13 *(B$22-B$23)/(J38*Aileron!B$7*Aileron!B$15)+E$8))*Aileron!B$11 +(Elevator!K38-Elevator!B$7)*Elevator!G$29)/ ((Aileron!B$11*Elevator!B$32)-(Elevator!G$29*Elevator!B$33)) -> -0.31707774 | M38: =L38*57.3 -> -18.168554 | N38: =-(( (B$13 *(B$22-B$23)/(J38*Aileron!B$7*Aileron!B$15)+E$8))*Aileron!B$11 +(Elevator!K38-Elevator!B$7)*R38)/ ((Aileron!B$11*Elevator!S38)-(R38*Elevator!B$33)) -> -0.35518356 | O38: =N38*57.3 -> -20.352018 | P38: =5.2414 -> 5.2414 | Q38: =P38*Aileron!B$8/(Aileron!B$7*Aileron!B$15) -> 0.79213459 | R38: =Aileron!B$11*((T38)/Aileron!B$15)-(H$3*H$6*(Aileron!B$8/Aileron!B$7)*(B$24/Aileron!B$15)*(1-Elevator!H$24)) -> -2.0296392 | S38: =-H$3*H$6*Q38*B$40*B$27 -> -2.2155541 | T38: 0.141472 | U38: =(2*Aileron!B$5*9.81)/(0.90434*Aileron!B$7*(Elevator!H38*0.514)^2) -> 2.4449838 | V38: =0.5*0.90434*(H38*0.514)^2 -> 444.51626 | W38: =-(( (B$13 *(B$22-B$23)/(V38*Aileron!B$7*Aileron!B$15)+E$8))*Aileron!B$11 +(U38-Elevator!B$7)*Elevator!G$29)/ ((Aileron!B$11*Elevator!B$32)-(Elevator!G$29*Elevator!B$33)) -> -0.43783351 | X38: =W38*57.3 -> -25.08786 | Y38: =-(( (B$13 *(B$22-B$23)/(V38*Aileron!B$7*Aileron!B$15)+E$8))*Aileron!B$11 +(U38-Elevator!B$7)*R38)/ ((Aileron!B$11*Elevator!S38)-(R38*Elevator!B$33)) -> -0.49420382 | Z38: =Y38*57.3 -> -28.317879
D39: bh | E39: =SQRT(Aileron!B8*Aileron!B17) -> 4.9095214 | F39: m | H39: 65 | I39: =B$34 -> 2.8540219 | J39: =0.5*1.225*(H39*0.514)^2 -> 683.68971 | K39: =(2*Aileron!B$5*9.81)/(1.225*Aileron!B$7*(Elevator!H39*0.514)^2) -> 1.5896613 | L39: =-(( (B$13 *(B$22-B$23)/(J39*Aileron!B$7*Aileron!B$15)+E$8))*Aileron!B$11 +(Elevator!K39-Elevator!B$7)*Elevator!G$29)/ ((Aileron!B$11*Elevator!B$32)-(Elevator!G$29*Elevator!B$33)) -> -0.27645224 | M39: =L39*57.3 -> -15.840713 | N39: =-(( (B$13 *(B$22-B$23)/(J39*Aileron!B$7*Aileron!B$15)+E$8))*Aileron!B$11 +(Elevator!K39-Elevator!B$7)*R39)/ ((Aileron!B$11*Elevator!S39)-(R39*Elevator!B$33)) -> -0.30841339 | O39: =N39*57.3 -> -17.672087 | P39: =5.2414 -> 5.2414 | Q39: =P39*Aileron!B$8/(Aileron!B$7*Aileron!B$15) -> 0.79213459 | R39: =Aileron!B$11*((T39)/Aileron!B$15)-(H$3*H$6*(Aileron!B$8/Aileron!B$7)*(B$24/Aileron!B$15)*(1-Elevator!H$24)) -> -2.0296392 | S39: =-H$3*H$6*Q39*B$40*B$27 -> -2.2155541 | T39: 0.141472 | U39: =(2*Aileron!B$5*9.81)/(0.90434*Aileron!B$7*(Elevator!H39*0.514)^2) -> 2.1533219 | V39: =0.5*0.90434*(H39*0.514)^2 -> 504.72486 | W39: =-(( (B$13 *(B$22-B$23)/(V39*Aileron!B$7*Aileron!B$15)+E$8))*Aileron!B$11 +(U39-Elevator!B$7)*Elevator!G$29)/ ((Aileron!B$11*Elevator!B$32)-(Elevator!G$29*Elevator!B$33)) -> -0.38280306 | X39: =W39*57.3 -> -21.934616 | Y39: =-(( (B$13 *(B$22-B$23)/(V39*Aileron!B$7*Aileron!B$15)+E$8))*Aileron!B$11 +(U39-Elevator!B$7)*R39)/ ((Aileron!B$11*Elevator!S39)-(R39*Elevator!B$33)) -> -0.43084994 | Z39: =Y39*57.3 -> -24.687702
A40: bE/bh | B40: 1 | C40: m | H40: 70 | I40: =B$34 -> 2.8540219 | J40: =0.5*1.225*(H40*0.514)^2 -> 792.91825 | K40: =(2*Aileron!B$5*9.81)/(1.225*Aileron!B$7*(Elevator!H40*0.514)^2) -> 1.3706773 | L40: =-(( (B$13 *(B$22-B$23)/(J40*Aileron!B$7*Aileron!B$15)+E$8))*Aileron!B$11 +(Elevator!K40-Elevator!B$7)*Elevator!G$29)/ ((Aileron!B$11*Elevator!B$32)-(Elevator!G$29*Elevator!B$33)) -> -0.2351346 | M40: =L40*57.3 -> -13.473213 | N40: =-(( (B$13 *(B$22-B$23)/(J40*Aileron!B$7*Aileron!B$15)+E$8))*Aileron!B$11 +(Elevator!K40-Elevator!B$7)*R40)/ ((Aileron!B$11*Elevator!S40)-(R40*Elevator!B$33)) -> -0.2608464 | O40: =N40*57.3 -> -14.946499 | P40: =5.2414 -> 5.2414 | Q40: =P40*Aileron!B$8/(Aileron!B$7*Aileron!B$15) -> 0.79213459 | R40: =Aileron!B$11*((T40)/Aileron!B$15)-(H$3*H$6*(Aileron!B$8/Aileron!B$7)*(B$24/Aileron!B$15)*(1-Elevator!H$24)) -> -2.0296392 | S40: =-H$3*H$6*Q40*B$40*B$27 -> -2.2155541 | T40: 0.141472 | U40: =(2*Aileron!B$5*9.81)/(0.90434*Aileron!B$7*(Elevator!H40*0.514)^2) -> 1.8566908 | V40: =0.5*0.90434*(H40*0.514)^2 -> 585.36138 | W40: =-(( (B$13 *(B$22-B$23)/(V40*Aileron!B$7*Aileron!B$15)+E$8))*Aileron!B$11 +(U40-Elevator!B$7)*Elevator!G$29)/ ((Aileron!B$11*Elevator!B$32)-(Elevator!G$29*Elevator!B$33)) -> -0.32683506 | X40: =W40*57.3 -> -18.727649 | Y40: =-(( (B$13 *(B$22-B$23)/(V40*Aileron!B$7*Aileron!B$15)+E$8))*Aileron!B$11 +(U40-Elevator!B$7)*R40)/ ((Aileron!B$11*Elevator!S40)-(R40*Elevator!B$33)) -> -0.36641669 | Z40: =Y40*57.3 -> -20.995676
A41: bE | B41: =B40*E39 -> 4.9095214 | C41: m | D41: CE | E41: =B29*B42 -> 0.45219276 | F41: m | H41: 80 | I41: =B$34 -> 2.8540219 | J41: =0.5*1.225*(H41*0.514)^2 -> 1035.6483 | K41: =(2*Aileron!B$5*9.81)/(1.225*Aileron!B$7*(Elevator!H41*0.514)^2) -> 1.0494248 | L41: =-(( (B$13 *(B$22-B$23)/(J41*Aileron!B$7*Aileron!B$15)+E$8))*Aileron!B$11 +(Elevator!K41-Elevator!B$7)*Elevator!G$29)/ ((Aileron!B$11*Elevator!B$32)-(Elevator!G$29*Elevator!B$33)) -> -0.17452105 | M41: =L41*57.3 -> -10.000056 | N41: =-(( (B$13 *(B$22-B$23)/(J41*Aileron!B$7*Aileron!B$15)+E$8))*Aileron!B$11 +(Elevator!K41-Elevator!B$7)*R41)/ ((Aileron!B$11*Elevator!S41)-(R41*Elevator!B$33)) -> -0.19106496 | O41: =N41*57.3 -> -10.948022 | P41: =5.2414 -> 5.2414 | Q41: =P41*Aileron!B$8/(Aileron!B$7*Aileron!B$15) -> 0.79213459 | R41: =Aileron!B$11*((T41)/Aileron!B$15)-(H$3*H$6*(Aileron!B$8/Aileron!B$7)*(B$24/Aileron!B$15)*(1-Elevator!H$24)) -> -2.0296392 | S41: =-H$3*H$6*Q41*B$40*B$27 -> -2.2155541 | T41: 0.141472 | U41: =(2*Aileron!B$5*9.81)/(0.90434*Aileron!B$7*(Elevator!H41*0.514)^2) -> 1.4215289 | V41: =0.5*0.90434*(H41*0.514)^2 -> 764.55363 | W41: =-(( (B$13 *(B$22-B$23)/(V41*Aileron!B$7*Aileron!B$15)+E$8))*Aileron!B$11 +(U41-Elevator!B$7)*Elevator!G$29)/ ((Aileron!B$11*Elevator!B$32)-(Elevator!G$29*Elevator!B$33)) -> -0.24472921 | X41: =W41*57.3 -> -14.022984 | Y41: =-(( (B$13 *(B$22-B$23)/(V41*Aileron!B$7*Aileron!B$15)+E$8))*Aileron!B$11 +(U41-Elevator!B$7)*R41)/ ((Aileron!B$11*Elevator!S41)-(R41*Elevator!B$33)) -> -0.27189221 | Z41: =Y41*57.3 -> -15.579423
A42: Ch | B42: =Aileron!B8/Elevator!E39 -> 1.2919793 | H42: 100 | I42: =B$34 -> 2.8540219 | J42: =0.5*1.225*(H42*0.514)^2 -> 1618.2005 | K42: =(2*Aileron!B$5*9.81)/(1.225*Aileron!B$7*(Elevator!H42*0.514)^2) -> 0.6716319 | L42: =-(( (B$13 *(B$22-B$23)/(J42*Aileron!B$7*Aileron!B$15)+E$8))*Aileron!B$11 +(Elevator!K42-Elevator!B$7)*Elevator!G$29)/ ((Aileron!B$11*Elevator!B$32)-(Elevator!G$29*Elevator!B$33)) -> -0.10323952 | M42: =L42*57.3 -> -5.9156245 | N42: =-(( (B$13 *(B$22-B$23)/(J42*Aileron!B$7*Aileron!B$15)+E$8))*Aileron!B$11 +(Elevator!K42-Elevator!B$7)*R42)/ ((Aileron!B$11*Elevator!S42)-(R42*Elevator!B$33)) -> -0.10900198 | O42: =N42*57.3 -> -6.2458134 | P42: =5.2414 -> 5.2414 | Q42: =P42*Aileron!B$8/(Aileron!B$7*Aileron!B$15) -> 0.79213459 | R42: =Aileron!B$11*((T42)/Aileron!B$15)-(H$3*H$6*(Aileron!B$8/Aileron!B$7)*(B$24/Aileron!B$15)*(1-Elevator!H$24)) -> -2.0296392 | S42: =-H$3*H$6*Q42*B$40*B$27 -> -2.2155541 | T42: 0.141472 | U42: =(2*Aileron!B$5*9.81)/(0.90434*Aileron!B$7*(Elevator!H42*0.514)^2) -> 0.90977849 | V42: =0.5*0.90434*(H42*0.514)^2 -> 1194.6151 | W42: =-(( (B$13 *(B$22-B$23)/(V42*Aileron!B$7*Aileron!B$15)+E$8))*Aileron!B$11 +(U42-Elevator!B$7)*Elevator!G$29)/ ((Aileron!B$11*Elevator!B$32)-(Elevator!G$29*Elevator!B$33)) -> -0.14817274 | X42: =W42*57.3 -> -8.4902981 | Y42: =-(( (B$13 *(B$22-B$23)/(V42*Aileron!B$7*Aileron!B$15)+E$8))*Aileron!B$11 +(U42-Elevator!B$7)*R42)/ ((Aileron!B$11*Elevator!S42)-(R42*Elevator!B$33)) -> -0.16073142 | Z42: =Y42*57.3 -> -9.2099104
...

Sheet Rudder
A2: Sv | B2: 3.9496 | C2: m2 | D2: Vw | E2: 20 | F2: Knots | G2: VMC | H2: =0.8*Aileron!D10 -> 25.0832 | I2: m/s | K2: VERTICAL TAIL PARAMETERS
A3: bV | B3: =SQRT(B2*K3) -> 2.3514761 | D3: lv | E3: =4.6-(0.17*1.7684) -> 4.299372 | F3: m | G3: dist_eng | H3: 4.122522 | I3: m | J3: ARVT | K3: 1.4 | M3: ClαVT | N3: 0.101 | O3: 1/deg
A4: CLαV | B4: =N4/(1+(N4/(3.142*K3))) -> 2.4992073 | C4: 1/rad | D4: U1 | E4: =1.1*Aileron!D10 -> 34.4894 | F4: m/s | J4: ɅC/4 | K4: 20 | L4: deg | M4: = | N4: =N3*57.3 -> 5.7873 | O4: 1/rad
A5: ηv | B5: 0.97 | D5: VT | E5: =SQRT(E4^2+(E2*0.514)^2) -> 35.988847 | F5: m/s | J5: t/c VT | K5: 0.09
A6: δα/δβ | B6: 0 | J6: CVT | K6: =B2/B3 -> 1.6796258
A7: Cno | B7: 0 | D7: xca | E7: =((B9*B12) + (B2*B13))/(B9+Rudder!B2) -> 5.6222312 | F7: m | J7: CrootVT | K7: =((3/2)*K6)/ ((1+K8+K8^2)/(1+K8)) -> 1.8118413
A8: Cyo | B8: 0 | C8: m2 | D8: dc | E8: =E7-(2.6+0.4*1.7684) -> 2.3148712 | F8: m | J8: λVT | K8: 0.85
A9: Sf | B9: 9.717 | C9: m2 | D9: Fw | E9: =0.5*1.225*(E2*0.514)^2*B10*E10 -> 721.84336 | F9: N
A10: Ss | B10: =1.02*(B9+B2) -> 13.939932 | D10: CDy | E10: 0.8
A11: Cv | B11: =B2/B3 -> 1.6796258 | C11: m | D11: bR/bV | E11: 1 | F11: CR/CV | G11: =0.3 -> 0.3
A12: xf | B12: =Elevator!B4/2 -> 4.55 | C12: m | D12: τr | E12: 0.51 | F12: obtain value from figure 12.12 Sadraey
A13: xv | B13: =Elevator!B4-B11+(B11/2) -> 8.2601871 | C13: m | D13: β | E13: =((ATAN((E2*0.514/E4)))) -> 0.28967841 | F13: rad
A14: Vv | B14: =B2*E3/(Aileron!B13*Aileron!B7) -> 0.051870507 | D14: = | E14: =E13*57.3 -> 16.598573 | F14: deg
D15: Kf1 | E15: 0.75 | F15: Kf1 | G15: 1.35
A16: CyδR | B16: =B4*B5*E12*E11*B2/Aileron!B7 -> 0.20387802 | C16: 1/rad | D16: Cnβ | E16: =E15*B4*(1-B6)*B5*E3*B2/(Aileron!B7*Aileron!B13) -> 0.094309571 | F16: 1/rad
A17: CnδR | B17: =-B4*B14*B5*E12*E11 -> -0.064130508 | C17: 1/rad | D17: Cyβ | E17: =-G15*B4*(1-B6)*B5*B2/Aileron!B7 -> -0.53967711 | F17: 1/rad
A19: δR(rads) | B19: deg | C19: a | D19: b | E19: total | F19: σ (rads) | G19: deg
A20: =(E$9/(0.5*1.225*E$5^2*Aileron!B$7*Rudder!B$16))-((Rudder!E$17*Rudder!E$13)/Rudder!B$16)+((Rudder!E$17*Rudder!F20)/Rudder!B$16) -> 2.2766642 | B20: =A20*57.3 -> 130.45286 | C20: =0.5*1.225*E$5^2*Aileron!B$7*Aileron!B$13 -> 259704.58 | D20: =C20*(B$7+E$16*(E$13-F20)+(B$17*A20)) -> -18576.512 | E20: =D20+(E$9*E$8*COS(F20)) -> -17110.094 | F20: -0.5 | G20: =F20*57.3 -> -28.65
A21: =(E$9/(0.5*1.225*E$5^2*Aileron!B$7*Rudder!B$16))-((Rudder!E$17*Rudder!E$13)/Rudder!B$16)+((Rudder!E$17*Rudder!F21)/Rudder!B$16) -> 1.4825465 | B21: =A21*57.3 -> 84.949916 | C21: =0.5*1.225*E$5^2*Aileron!B$7*Aileron!B$13 -> 259704.58 | D21: =C21*(B$7+E$16*(E$13-F21)+(B$17*A21)) -> -12698.282 | E21: =D21+(E$9*E$8*COS(F21)) -> -11060.616 | F21: -0.2 | G21: =F21*57.3 -> -11.46
A22: =(E$9/(0.5*1.225*E$5^2*Aileron!B$7*Rudder!B$16))-((Rudder!E$17*Rudder!E$13)/Rudder!B$16)+((Rudder!E$17*Rudder!F22)/Rudder!B$16) -> 1.2178407 | B22: =A22*57.3 -> 69.782269 | C22: =0.5*1.225*E$5^2*Aileron!B$7*Aileron!B$13 -> 259704.58 | D22: =C22*(B$7+E$16*(E$13-F22)+(B$17*A22)) -> -10738.872 | E22: =D22+(E$9*E$8*COS(F22)) -> -9076.2451 | F22: -0.1 | G22: =F22*57.3 -> -5.73
A23: =(E$9/(0.5*1.225*E$5^2*Aileron!B$7*Rudder!B$16))-((Rudder!E$17*Rudder!E$13)/Rudder!B$16)+((Rudder!E$17*Rudder!F23)/Rudder!B$16) -> 0.95313477 | B23: =A23*57.3 -> 54.614622 | C23: =0.5*1.225*E$5^2*Aileron!B$7*Aileron!B$13 -> 259704.58 | D23: =C23*(B$7+E$16*(E$13-F23)+(B$17*A23)) -> -8779.4614 | E23: =D23+(E$9*E$8*COS(F23)) -> -7108.487 | F23: 0 | G23: =F23*57.3 -> 0
A24: =(E$9/(0.5*1.225*E$5^2*Aileron!B$7*Rudder!B$16))-((Rudder!E$17*Rudder!E$13)/Rudder!B$16)+((Rudder!E$17*Rudder!F24)/Rudder!B$16) -> 0.02666418 | B24: =A24*57.3 -> 1.5278575 | C24: =0.5*1.225*E$5^2*Aileron!B$7*Aileron!B$13 -> 259704.58 | D24: =C24*(B$7+E$16*(E$13-F24)+(B$17*A24)) -> -1921.5258 | E24: =D24+(E$9*E$8*COS(F24)) -> -351.858 | F24: 0.35 | G24: =F24*57.3 -> 20.055
A25: =(E$9/(0.5*1.225*E$5^2*Aileron!B$7*Rudder!B$16))-((Rudder!E$17*Rudder!E$13)/Rudder!B$16)+((Rudder!E$17*Rudder!F25)/Rudder!B$16) -> -0.0097064085 | B25: =A25*57.3 -> -0.55617721 | C25: =0.5*1.225*E$5^2*Aileron!B$7*Aileron!B$13 -> 259704.58 | D25: =C25*(B$7+E$16*(E$13-F25)+(B$17*A25)) -> -1652.3028 | E25: =D25+(E$9*E$8*COS(F25)) -> -90.655615 | F25: 0.36374 | G25: =F25*57.3 -> 20.842302
A26: =(E$9/(0.5*1.225*E$5^2*Aileron!B$7*Rudder!B$16))-((Rudder!E$17*Rudder!E$13)/Rudder!B$16)+((Rudder!E$17*Rudder!F26)/Rudder!B$16) -> -0.020982879 | B26: =A26*57.3 -> -1.202319 | C26: =0.5*1.225*E$5^2*Aileron!B$7*Aileron!B$13 -> 259704.58 | D26: =C26*(B$7+E$16*(E$13-F26)+(B$17*A26)) -> -1568.8319 | E26: =D26+(E$9*E$8*COS(F26)) -> -9.7314135 | F26: 0.368 | G26: =F26*57.3 -> 21.0864
C28: change the values in the σ column till the corresponding value in total column on the left is as close
C29: to zero as possible. Pick the value of σ(deg ) and the δR(deg) on the same row
G31: δR (rads) | H31: 0.368
A32: Assymetric thrust requirement | G32: = | H32: =H31*57.3 -> 21.0864 | J32: δR must aleays be less than δR req
B33: δR | C33: =(Elevator!B13*Rudder!H3/4)/(-0.5*1.225*Rudder!H2^2*Aileron!B7*Aileron!B13*Rudder!B17) -> 0.48407459 | D33: rad | G33: δR req | H33: 30 | K33: inorder to satisfy the requirements i.e
B34: = | C34: =C33*57.3 -> 27.737474 | D34: deg | K34: FAR PART 23
B35: δR req | C35: 30 | D35: deg
E36: new VMC | F36: =SQRT((Elevator!B13*3.5/4)/(-0.5*1.225*Aileron!B7*Aileron!B13*Rudder!B17*Rudder!H33/57.3)) -> 22.223287 | G36: m/s
A37: Geometry | E37: = | F37: =F36/0.514 -> 43.235967 | G37: knots
A38: CR | B38: =G11*B11 -> 0.50388774 | C38: m
A39: bR | B39: =E11*B3 -> 2.3514761 | C39: m
A40: SR | B40: =B38*B39 -> 1.18488 | C40: m2
